<?xml version="1.0" ?>
<robot name="Robot">
  <!--Generated by CROSS, a ROS Workbench for FreeCAD (https://github.com/galou/freecad.cross)-->
  <link name="base_link">
    <visual>
      <!--Box_Chassis/Body001.-->
      <origin rpy="0.0 -0.0 0.0" xyz="0.0 0.0 0.0"/>
      <geometry>
        <mesh filename="package://first_robot_freecad/meshes/first_robot_Body001.dae"/>
      </geometry>
    </visual>
    <collision>
      <!--Box_Chassis/Body001.-->
      <origin rpy="0.0 -0.0 0.0" xyz="0.0 0.0 0.0"/>
      <geometry>
        <mesh filename="package://first_robot_freecad/meshes/first_robot_Body001.dae"/>
      </geometry>
    </collision>
    <inertial>
      <mass value="6.4799999999999995"/>
      <origin rpy="0.0 -0.0 0.0" xyz="-0.15 -8.7e-18 4e-19"/>
      <inertia ixx="0.022464" ixy="0.0" ixz="-0.0" iyy="0.049464" iyz="0.0" izz="0.0702"/>
    </inertial>
  </link>
  <link name="left_wheel">
    <visual>
      <!--Adjustable Wheel/Body.-->
      <origin rpy="0.0 -0.0 0.0" xyz="0.0 0.0 0.0"/>
      <geometry>
        <mesh filename="package://first_robot_freecad/meshes/first_robot_Body.dae"/>
      </geometry>
    </visual>
    <collision>
      <!--Adjustable Wheel.Body_bbox-->
      <origin rpy="0.0 -0.0 0.0" xyz="0.0 0.0 0.015"/>
      <geometry>
        <cylinder length="0.03000000000000005" radius="0.06"/>
      </geometry>
    </collision>
    <inertial>
      <mass value="0.7509245446194294"/>
      <origin rpy="0.0 -0.0 0.0" xyz="-1.38e-17 -2.1e-18 -1e-19"/>
      <inertia ixx="0.0006186158699452" ixy="-0.0" ixz="-0.0" iyy="0.0011245930581975" iyz="-0.0" izz="0.0006186158699452"/>
    </inertial>
  </link>
  <link name="right_wheel">
    <visual>
      <!--Adjustable Wheel/Body.-->
      <origin rpy="0.0 -0.0 0.0" xyz="0.0 0.0 0.0"/>
      <geometry>
        <mesh filename="package://first_robot_freecad/meshes/first_robot_Body.dae"/>
      </geometry>
    </visual>
    <collision>
      <!--Adjustable Wheel.Body_bbox-->
      <origin rpy="0.0 -0.0 0.0" xyz="0.0 0.0 0.015"/>
      <geometry>
        <cylinder length="0.03000000000000005" radius="0.06"/>
      </geometry>
    </collision>
    <inertial>
      <mass value="0.7509245446194294"/>
      <origin rpy="0.0 -0.0 0.0" xyz="-1.38e-17 -2.1e-18 -1e-19"/>
      <inertia ixx="0.0006186158699452" ixy="-0.0" ixz="-0.0" iyy="0.0011245930581975" iyz="-0.0" izz="0.0006186158699452"/>
    </inertial>
  </link>
  <link name="caster_wheel">
    <visual>
      <!--Sphere001-->
      <geometry>
        <sphere radius="0.02"/>
      </geometry>
    </visual>
    <collision>
      <!--Sphere001-->
      <geometry>
        <sphere radius="0.02"/>
      </geometry>
    </collision>
    <inertial>
      <mass value="0.0"/>
      <origin rpy="0.0 -0.0 0.0" xyz="0.0 0.0 0.0"/>
      <inertia ixx="0.0" ixy="0.0" ixz="0.0" iyy="0.0" iyz="0.0" izz="0.0"/>
    </inertial>
  </link>
  <joint name="left_wheel_joint" type="continuous">
    <parent link="base_link"/>
    <child link="left_wheel"/>
    <origin rpy="-1.5707963267948966 0.0 0.0" xyz="0.0 0.12 0.0"/>
    <axis xyz="0 0 1"/>
  </joint>
  <joint name="right_wheel_joint" type="continuous">
    <parent link="base_link"/>
    <child link="right_wheel"/>
    <origin rpy="-1.5707963267948966 0.0 0.0" xyz="0.0 -0.12 0.0"/>
    <axis xyz="0 0 1"/>
  </joint>
  <joint name="caster_wheel_joint" type="fixed">
    <parent link="base_link"/>
    <child link="caster_wheel"/>
    <origin rpy="0.0 -0.0 0.0" xyz="-0.25 0.0 -0.04"/>
  </joint>
</robot>
