<?xml version="1.0" ?>
<robot name="my_robot_arm">
  <!--Generated by CROSS, a ROS Workbench for FreeCAD (https://github.com/galou/freecad.cross)-->
  <link name="base_link">
    <visual>
      <!--Base_Link_Part/Body.-->
      <origin rpy="0.0 -0.0 0.0" xyz="0.0 0.0 0.0"/>
      <geometry>
        <mesh filename="package://my_robot_arm/meshes/Test2_Base_Link_Body.dae"/>
      </geometry>
    </visual>
    <collision>
      <!--Base_Link_Part/Body.-->
      <origin rpy="0.0 -0.0 0.0" xyz="0.0 0.0 0.0"/>
      <geometry>
        <mesh filename="package://my_robot_arm/meshes/Test2_Base_Link_Body.dae"/>
      </geometry>
    </collision>
    <inertial>
      <mass value="0.0"/>
      <origin rpy="0.0 -0.0 0.0" xyz="0.0 0.0 0.0"/>
      <inertia ixx="0.0" ixy="0.0" ixz="0.0" iyy="0.0" iyz="0.0" izz="0.0"/>
    </inertial>
  </link>
  <link name="finger_link">
    <visual>
      <!--finger_part/Body001.-->
      <origin rpy="0.0 -0.0 0.0" xyz="0.0 0.0 0.0"/>
      <geometry>
        <mesh filename="package://my_robot_arm/meshes/Test2_finger_body.dae"/>
      </geometry>
    </visual>
    <collision>
      <!--finger_part/Body001.-->
      <origin rpy="0.0 -0.0 0.0" xyz="0.0 0.0 0.0"/>
      <geometry>
        <mesh filename="package://my_robot_arm/meshes/Test2_finger_body.dae"/>
      </geometry>
    </collision>
    <inertial>
      <mass value="0.0"/>
      <origin rpy="0.0 -0.0 0.0" xyz="0.0 0.0 0.0"/>
      <inertia ixx="0.0" ixy="0.0" ixz="0.0" iyy="0.0" iyz="0.0" izz="0.0"/>
    </inertial>
  </link>
  <joint name="finger_joint" type="prismatic">
    <parent link="base_link"/>
    <child link="finger_link"/>
    <origin rpy="0.0 -0.0 0.0" xyz="-0.05956 0.0 0.06"/>
    <axis xyz="1 0 0"/>
    <limit effort="1000.0" lower="0.00" upper="0.078" velocity="1"/>
  </joint>
</robot>
